Workbook

Sheet Summary
A1: Commission Invoices — Summary
A2: Number of invoices: | B2: =COUNTA(A5:A30) -> 26
A4: Invoice | B4: Customer | C4: Brand | D4: Month | E4: POs | F4: Received (SAR) | G4: Commission (SAR)
A5: INV-SONDOS-2025-09 | B5: Alaris Group | C5: SONDOS | D5: 45901 | E5: =COUNTA(SONDOS!$A$6:$A$6) -> 1 | F5: =SONDOS!$C$7 -> 205.6 | G5: =SONDOS!$E$7 -> 12.34
A6: INV-MARAH-2025-10 | B6: Alaris Group | C6: Marah | D6: 45931 | E6: =COUNTA(Marah!$A$6:$A$7) -> 2 | F6: =Marah!$C$8 -> 398 | G6: =Marah!$E$8 -> 23.88
A7: INV-SONDOS-2025-10 | B7: Alaris Group | C7: SONDOS | D7: 45931 | E7: =COUNTA(SONDOS!$A$10:$A$10) -> 1 | F7: =SONDOS!$C$11 -> 1101.6 | G7: =SONDOS!$E$11 -> 66.1
A8: INV-MARAH-2025-11 | B8: Alaris Group | C8: Marah | D8: 45962 | E8: =COUNTA(Marah!$A$11:$A$13) -> 3 | F8: =Marah!$C$14 -> 2358.2 | G8: =Marah!$E$14 -> 141.49
A9: INV-SONDOS-2025-11 | B9: Alaris Group | C9: SONDOS | D9: 45962 | E9: =COUNTA(SONDOS!$A$14:$A$15) -> 2 | F9: =SONDOS!$C$16 -> 4409.7 | G9: =SONDOS!$E$16 -> 264.59
A10: INV-MARAH-2025-12 | B10: Alaris Group | C10: Marah | D10: 45992 | E10: =COUNTA(Marah!$A$17:$A$24) -> 8 | F10: =Marah!$C$25 -> 2085.7 | G10: =Marah!$E$25 -> 125.15
A11: INV-SONDOS-2025-12 | B11: Alaris Group | C11: SONDOS | D11: 45992 | E11: =COUNTA(SONDOS!$A$19:$A$23) -> 5 | F11: =SONDOS!$C$24 -> 713.9 | G11: =SONDOS!$E$24 -> 42.83
A12: INV-MARAH-2026-01 | B12: Alaris Group | C12: Marah | D12: 46023 | E12: =COUNTA(Marah!$A$28:$A$33) -> 6 | F12: =Marah!$C$34 -> 4595.5 | G12: =Marah!$E$34 -> 275.73
A13: INV-SONDOS-2026-01 | B13: Alaris Group | C13: SONDOS | D13: 46023 | E13: =COUNTA(SONDOS!$A$27:$A$30) -> 4 | F13: =SONDOS!$C$31 -> 421.9 | G13: =SONDOS!$E$31 -> 25.32
A14: INV-MARAH-2026-02 | B14: Alaris Group | C14: Marah | D14: 46054 | E14: =COUNTA(Marah!$A$37:$A$44) -> 8 | F14: =Marah!$C$45 -> 2941.54 | G14: =Marah!$E$45 -> 176.49
A15: INV-SONDOS-2026-02 | B15: Alaris Group | C15: SONDOS | D15: 46054 | E15: =COUNTA(SONDOS!$A$34:$A$38) -> 5 | F15: =SONDOS!$C$39 -> 1566.1 | G15: =SONDOS!$E$39 -> 93.96
A16: INV-MARAH-2026-03 | B16: Alaris Group | C16: Marah | D16: 46082 | E16: =COUNTA(Marah!$A$48:$A$56) -> 9 | F16: =Marah!$C$57 -> 1647.8 | G16: =Marah!$E$57 -> 98.86
A17: INV-SONDOS-2026-03 | B17: Alaris Group | C17: SONDOS | D17: 46082 | E17: =COUNTA(SONDOS!$A$42:$A$48) -> 7 | F17: =SONDOS!$C$49 -> 2351 | G17: =SONDOS!$E$49 -> 141.06
A18: INV-MARAH-2026-04 | B18: Alaris Group | C18: Marah | D18: 46113 | E18: =COUNTA(Marah!$A$60:$A$67) -> 8 | F18: =Marah!$C$68 -> 9314.84 | G18: =Marah!$E$68 -> 558.88
A19: INV-SONDOS-2026-04 | B19: Alaris Group | C19: SONDOS | D19: 46113 | E19: =COUNTA(SONDOS!$A$52:$A$55) -> 4 | F19: =SONDOS!$C$56 -> 2428.4 | G19: =SONDOS!$E$56 -> 145.71
A20: INV-MARAH-2026-05 | B20: Alaris Group | C20: Marah | D20: 46143 | E20: =COUNTA(Marah!$A$71:$A$82) -> 12 | F20: =Marah!$C$83 -> 6281.3 | G20: =Marah!$E$83 -> 376.86
A21: INV-SONDOS-2026-05 | B21: Alaris Group | C21: SONDOS | D21: 46143 | E21: =COUNTA(SONDOS!$A$59:$A$63) -> 5 | F21: =SONDOS!$C$64 -> 2325.6 | G21: =SONDOS!$E$64 -> 139.53
A22: INV-MARAH-2026-06 | B22: Alaris Group | C22: Marah | D22: 46174 | E22: =COUNTA(Marah!$A$86:$A$93) -> 8 | F22: =Marah!$C$94 -> 2430.1 | G22: =Marah!$E$94 -> 145.79
A23: INV-SONDOS-2026-06 | B23: Alaris Group | C23: SONDOS | D23: 46174 | E23: =COUNTA(SONDOS!$A$67:$A$72) -> 6 | F23: =SONDOS!$C$73 -> 1751 | G23: =SONDOS!$E$73 -> 105.06
A24: INV-WADIHALFA-2026-06 | B24: Wadi Halfa | C24: Wadi Halfa | D24: 46174 | E24: =COUNTA('Wadi Halfa'!$A$6:$A$7) -> 2 | F24: ='Wadi Halfa'!$C$8 -> 953.85 | G24: ='Wadi Halfa'!$E$8 -> 38.15
A25: INV-MARAH-2026-07 | B25: Alaris Group | C25: Marah | D25: 46204 | E25: =COUNTA(Marah!$A$97:$A$107) -> 11 | F25: =Marah!$C$108 -> 5445.3 | G25: =Marah!$E$108 -> 326.71
A26: INV-SONDOS-2026-07 | B26: Alaris Group | C26: SONDOS | D26: 46204 | E26: =COUNTA(SONDOS!$A$76:$A$80) -> 5 | F26: =SONDOS!$C$81 -> 589.3 | G26: =SONDOS!$E$81 -> 35.35
A27: INV-WADIHALFA-2026-07 | B27: Wadi Halfa | C27: Wadi Halfa | D27: 46204 | E27: =COUNTA('Wadi Halfa'!$A$11:$A$15) -> 5 | F27: ='Wadi Halfa'!$C$16 -> 3775.34 | G27: ='Wadi Halfa'!$E$16 -> 151.02
A28: INV-MARAH-2026-08 | B28: Alaris Group | C28: Marah | D28: 46235 | E28: =COUNTA(Marah!$A$111:$A$113) -> 3 | F28: =Marah!$C$114 -> 930.8 | G28: =Marah!$E$114 -> 55.85
A29: INV-SONDOS-2026-08 | B29: Alaris Group | C29: SONDOS | D29: 46235 | E29: =COUNTA(SONDOS!$A$84:$A$84) -> 1 | F29: =SONDOS!$C$85 -> 244.8 | G29: =SONDOS!$E$85 -> 14.69
A30: INV-WADIHALFA-2026-08 | B30: Wadi Halfa | C30: Wadi Halfa | D30: 46235 | E30: =COUNTA('Wadi Halfa'!$A$19:$A$20) -> 2 | F30: ='Wadi Halfa'!$C$21 -> 3223.77 | G30: ='Wadi Halfa'!$E$21 -> 128.95
A31: Total | E31: =SUM(E5:E30) -> 133 | F31: =SUM(F5:F30) -> 64490.94 | G31: =SUM(G5:G30) -> 3710.35

Sheet Marah
A1: Marah — Commission Invoices — Customer: Alaris Group
A2: Commission rate (of received): | B2: 0.06 | C2: Commission per PO = ROUND(Received × rate, 2).
A4: Description | B4: Month | C4: Received (SAR) | D4: Commission % | E4: Nasam Commission (SAR)
A5: INV-MARAH-2025-10 · Alaris Group · Oct 2025
A6: Amazon Retail PO#4TN3ZVSL | B6: 45931 | C6: 288 | D6: =$B$2 -> 0.06 | E6: =ROUND(C6*$B$2,2) -> 17.28
A7: Amazon Retail PO#6PP725QB | B7: 45931 | C7: 110 | D7: =$B$2 -> 0.06 | E7: =ROUND(C7*$B$2,2) -> 6.6
A8: Invoice total | C8: =SUM(C6:C7) -> 398 | E8: =SUM(E6:E7) -> 23.88
A10: INV-MARAH-2025-11 · Alaris Group · Nov 2025
A11: Amazon Retail PO#2P93YCEF | B11: 45962 | C11: 110.4 | D11: =$B$2 -> 0.06 | E11: =ROUND(C11*$B$2,2) -> 6.62
A12: Amazon Retail PO#6DY1IPME | B12: 45962 | C12: 244.8 | D12: =$B$2 -> 0.06 | E12: =ROUND(C12*$B$2,2) -> 14.69
A13: Amazon Retail PO#6WB73PWY | B13: 45962 | C13: 2003 | D13: =$B$2 -> 0.06 | E13: =ROUND(C13*$B$2,2) -> 120.18
A14: Invoice total | C14: =SUM(C11:C13) -> 2358.2 | E14: =SUM(E11:E13) -> 141.49
A16: INV-MARAH-2025-12 · Alaris Group · Dec 2025
A17: Amazon Retail PO#5EN36W7Q | B17: 45992 | C17: 220.8 | D17: =$B$2 -> 0.06 | E17: =ROUND(C17*$B$2,2) -> 13.25
A18: Amazon Retail PO#6CZVU75G | B18: 45992 | C18: 136.8 | D18: =$B$2 -> 0.06 | E18: =ROUND(C18*$B$2,2) -> 8.21
A19: Amazon Retail PO#7M6TKRHR | B19: 45992 | C19: 143 | D19: =$B$2 -> 0.06 | E19: =ROUND(C19*$B$2,2) -> 8.58
A20: Amazon Retail PO#6TDL7ZQP | B20: 45992 | C20: 333.5 | D20: =$B$2 -> 0.06 | E20: =ROUND(C20*$B$2,2) -> 20.01
A21: Amazon Retail PO#6PSDP49U | B21: 45992 | C21: 349.2 | D21: =$B$2 -> 0.06 | E21: =ROUND(C21*$B$2,2) -> 20.95
A22: Amazon Retail PO#797EACNS | B22: 45992 | C22: 609.6 | D22: =$B$2 -> 0.06 | E22: =ROUND(C22*$B$2,2) -> 36.58
A23: Amazon Retail PO#6UBMEEFU | B23: 45992 | C23: 73.2 | D23: =$B$2 -> 0.06 | E23: =ROUND(C23*$B$2,2) -> 4.39
A24: Amazon Retail PO#6V3M52MA | B24: 45992 | C24: 219.6 | D24: =$B$2 -> 0.06 | E24: =ROUND(C24*$B$2,2) -> 13.18
A25: Invoice total | C25: =SUM(C17:C24) -> 2085.7 | E25: =SUM(E17:E24) -> 125.15
A27: INV-MARAH-2026-01 · Alaris Group · Jan 2026
A28: Amazon Retail PO#6PH6KTZF | B28: 46023 | C28: 73.2 | D28: =$B$2 -> 0.06 | E28: =ROUND(C28*$B$2,2) -> 4.39
A29: Amazon Retail PO#6S9RVIGN | B29: 46023 | C29: 1209.6 | D29: =$B$2 -> 0.06 | E29: =ROUND(C29*$B$2,2) -> 72.58
A30: Amazon Retail PO#8GLJBAPU | B30: 46023 | C30: 1888.2 | D30: =$B$2 -> 0.06 | E30: =ROUND(C30*$B$2,2) -> 113.29
A31: Amazon Retail PO#2B5T42JL | B31: 46023 | C31: 379.5 | D31: =$B$2 -> 0.06 | E31: =ROUND(C31*$B$2,2) -> 22.77
A32: Amazon Retail PO#4MD92H1G | B32: 46023 | C32: 990 | D32: =$B$2 -> 0.06 | E32: =ROUND(C32*$B$2,2) -> 59.4
A33: Amazon Retail PO#3NBXS26G | B33: 46023 | C33: 55 | D33: =$B$2 -> 0.06 | E33: =ROUND(C33*$B$2,2) -> 3.3
A34: Invoice total | C34: =SUM(C28:C33) -> 4595.5 | E34: =SUM(E28:E33) -> 275.73
A36: INV-MARAH-2026-02 · Alaris Group · Feb 2026
A37: Amazon Retail PO#2776KBES | B37: 46054 | C37: 218.4 | D37: =$B$2 -> 0.06 | E37: =ROUND(C37*$B$2,2) -> 13.1
A38: Amazon Retail PO#35A5IQ5O | B38: 46054 | C38: 55.2 | D38: =$B$2 -> 0.06 | E38: =ROUND(C38*$B$2,2) -> 3.31
A39: Amazon Retail PO#2NMPDC6A | B39: 46054 | C39: 1120.82 | D39: =$B$2 -> 0.06 | E39: =ROUND(C39*$B$2,2) -> 67.25
A40: Amazon Retail PO#63CNSAWW | B40: 46054 | C40: 386.4 | D40: =$B$2 -> 0.06 | E40: =ROUND(C40*$B$2,2) -> 23.18
A41: Amazon Retail PO#2Q2CPLWE | B41: 46054 | C41: 55 | D41: =$B$2 -> 0.06 | E41: =ROUND(C41*$B$2,2) -> 3.3
A42: Amazon Retail PO#47SZZRUF | B42: 46054 | C42: 794.92 | D42: =$B$2 -> 0.06 | E42: =ROUND(C42*$B$2,2) -> 47.7
A43: Amazon Retail PO#5CHSK8EF | B43: 46054 | C43: 219.6 | D43: =$B$2 -> 0.06 | E43: =ROUND(C43*$B$2,2) -> 13.18
A44: Amazon Retail PO#8MME3VWE | B44: 46054 | C44: 91.2 | D44: =$B$2 -> 0.06 | E44: =ROUND(C44*$B$2,2) -> 5.47
A45: Invoice total | C45: =SUM(C37:C44) -> 2941.54 | E45: =SUM(E37:E44) -> 176.49
...

Sheet SONDOS
A1: SONDOS — Commission Invoices — Customer: Alaris Group
A2: Commission rate (of received): | B2: 0.06 | C2: Commission per PO = ROUND(Received × rate, 2).
A4: Description | B4: Month | C4: Received (SAR) | D4: Commission % | E4: Nasam Commission (SAR)
A5: INV-SONDOS-2025-09 · Alaris Group · Sep 2025
A6: Amazon Retail PO#32EZOEJU | B6: 45901 | C6: 205.6 | D6: =$B$2 -> 0.06 | E6: =ROUND(C6*$B$2,2) -> 12.34
A7: Invoice total | C7: =SUM(C6:C6) -> 205.6 | E7: =SUM(E6:E6) -> 12.34
A9: INV-SONDOS-2025-10 · Alaris Group · Oct 2025
A10: Amazon Retail PO#6PP725QB | B10: 45931 | C10: 1101.6 | D10: =$B$2 -> 0.06 | E10: =ROUND(C10*$B$2,2) -> 66.1
A11: Invoice total | C11: =SUM(C10:C10) -> 1101.6 | E11: =SUM(E10:E10) -> 66.1
A13: INV-SONDOS-2025-11 · Alaris Group · Nov 2025
A14: Amazon Retail PO#6DY1IPME | B14: 45962 | C14: 1898.25 | D14: =$B$2 -> 0.06 | E14: =ROUND(C14*$B$2,2) -> 113.9
A15: Amazon Retail PO#6WB73PWY | B15: 45962 | C15: 2511.45 | D15: =$B$2 -> 0.06 | E15: =ROUND(C15*$B$2,2) -> 150.69
A16: Invoice total | C16: =SUM(C14:C15) -> 4409.7 | E16: =SUM(E14:E15) -> 264.59
A18: INV-SONDOS-2025-12 · Alaris Group · Dec 2025
A19: Amazon Retail PO#6CZVU75G | B19: 45992 | C19: 239.94 | D19: =$B$2 -> 0.06 | E19: =ROUND(C19*$B$2,2) -> 14.4
A20: Amazon Retail PO#7M6TKRHR | B20: 45992 | C20: 26.66 | D20: =$B$2 -> 0.06 | E20: =ROUND(C20*$B$2,2) -> 1.6
A21: Amazon Retail PO#6UBMEEFU | B21: 45992 | C21: 70.5 | D21: =$B$2 -> 0.06 | E21: =ROUND(C21*$B$2,2) -> 4.23
A22: Amazon Retail PO#6V3M52MA | B22: 45992 | C22: 122.4 | D22: =$B$2 -> 0.06 | E22: =ROUND(C22*$B$2,2) -> 7.34
A23: Amazon Retail PO#5ILLL7BX | B23: 45992 | C23: 254.4 | D23: =$B$2 -> 0.06 | E23: =ROUND(C23*$B$2,2) -> 15.26
A24: Invoice total | C24: =SUM(C19:C23) -> 713.9 | E24: =SUM(E19:E23) -> 42.83
A26: INV-SONDOS-2026-01 · Alaris Group · Jan 2026
A27: Amazon Retail PO#1G7W4QOA | B27: 46023 | C27: 124.8 | D27: =$B$2 -> 0.06 | E27: =ROUND(C27*$B$2,2) -> 7.49
A28: Amazon Retail PO#6PH6KTZF | B28: 46023 | C28: 102.8 | D28: =$B$2 -> 0.06 | E28: =ROUND(C28*$B$2,2) -> 6.17
A29: Amazon Retail PO#6S9RVIGN | B29: 46023 | C29: 76.8 | D29: =$B$2 -> 0.06 | E29: =ROUND(C29*$B$2,2) -> 4.61
A30: Amazon Retail PO#4Q9D66FC | B30: 46023 | C30: 117.5 | D30: =$B$2 -> 0.06 | E30: =ROUND(C30*$B$2,2) -> 7.05
A31: Invoice total | C31: =SUM(C27:C30) -> 421.9 | E31: =SUM(E27:E30) -> 25.32
A33: INV-SONDOS-2026-02 · Alaris Group · Feb 2026
A34: Amazon Retail PO#2776KBES | B34: 46054 | C34: 390.7 | D34: =$B$2 -> 0.06 | E34: =ROUND(C34*$B$2,2) -> 23.44
A35: Amazon Retail PO#2NMPDC6A | B35: 46054 | C35: 135 | D35: =$B$2 -> 0.06 | E35: =ROUND(C35*$B$2,2) -> 8.1
A36: Amazon Retail PO#47SZZRUF | B36: 46054 | C36: 61.2 | D36: =$B$2 -> 0.06 | E36: =ROUND(C36*$B$2,2) -> 3.67
A37: Amazon Retail PO#85YJNW7Z | B37: 46054 | C37: 612 | D37: =$B$2 -> 0.06 | E37: =ROUND(C37*$B$2,2) -> 36.72
A38: Amazon Retail PO#8MME3VWE | B38: 46054 | C38: 367.2 | D38: =$B$2 -> 0.06 | E38: =ROUND(C38*$B$2,2) -> 22.03
A39: Invoice total | C39: =SUM(C34:C38) -> 1566.1 | E39: =SUM(E34:E38) -> 93.96
A41: INV-SONDOS-2026-03 · Alaris Group · Mar 2026
A42: Amazon Retail PO#33272MDV | B42: 46082 | C42: 244.8 | D42: =$B$2 -> 0.06 | E42: =ROUND(C42*$B$2,2) -> 14.69
A43: Amazon Retail PO#4VGJUUTB | B43: 46082 | C43: 244.8 | D43: =$B$2 -> 0.06 | E43: =ROUND(C43*$B$2,2) -> 14.69
A44: Amazon Retail PO#56ODNFEU | B44: 46082 | C44: 122.4 | D44: =$B$2 -> 0.06 | E44: =ROUND(C44*$B$2,2) -> 7.34
A45: Amazon Retail PO#3EO1QUXF | B45: 46082 | C45: 102.8 | D45: =$B$2 -> 0.06 | E45: =ROUND(C45*$B$2,2) -> 6.17
A46: Amazon Retail PO#1KBAMBMY | B46: 46082 | C46: 412.2 | D46: =$B$2 -> 0.06 | E46: =ROUND(C46*$B$2,2) -> 24.73
A47: Amazon Retail PO#1Y1T5K2Z | B47: 46082 | C47: 612 | D47: =$B$2 -> 0.06 | E47: =ROUND(C47*$B$2,2) -> 36.72
...

Sheet Wadi Halfa
A1: Wadi Halfa — Commission Invoices — Customer: Wadi Halfa
A2: Commission rate (of received): | B2: 0.04 | C2: Commission per PO = ROUND(Received × rate, 2).
A4: Description | B4: Month | C4: Received (SAR) | D4: Commission % | E4: Nasam Commission (SAR)
A5: INV-WADIHALFA-2026-06 · Wadi Halfa · Jun 2026
A6: Amazon Retail PO#523FHETX | B6: 46174 | C6: 321.75 | D6: =$B$2 -> 0.04 | E6: =ROUND(C6*$B$2,2) -> 12.87
A7: Amazon Retail PO#4KDCOEYS | B7: 46174 | C7: 632.1 | D7: =$B$2 -> 0.04 | E7: =ROUND(C7*$B$2,2) -> 25.28
A8: Invoice total | C8: =SUM(C6:C7) -> 953.85 | E8: =SUM(E6:E7) -> 38.15
A10: INV-WADIHALFA-2026-07 · Wadi Halfa · Jul 2026
A11: Ninja PO#2600607394 | B11: 46204 | C11: 1633.44 | D11: =$B$2 -> 0.04 | E11: =ROUND(C11*$B$2,2) -> 65.34
A12: Ninja PO#2600607555 | B12: 46204 | C12: 884.78 | D12: =$B$2 -> 0.04 | E12: =ROUND(C12*$B$2,2) -> 35.39
A13: Amazon Retail PO#6WAWK77S | B13: 46204 | C13: 948.15 | D13: =$B$2 -> 0.04 | E13: =ROUND(C13*$B$2,2) -> 37.93
A14: Ninja PO#2600629370 | B14: 46204 | C14: 240.91 | D14: =$B$2 -> 0.04 | E14: =ROUND(C14*$B$2,2) -> 9.64
A15: Ninja PO#2600629540 | B15: 46204 | C15: 68.06 | D15: =$B$2 -> 0.04 | E15: =ROUND(C15*$B$2,2) -> 2.72
A16: Invoice total | C16: =SUM(C11:C15) -> 3775.34 | E16: =SUM(E11:E15) -> 151.02
A18: INV-WADIHALFA-2026-08 · Wadi Halfa · Aug 2026
A19: Ninja PO#2600651634 | B19: 46235 | C19: 2008.6 | D19: =$B$2 -> 0.04 | E19: =ROUND(C19*$B$2,2) -> 80.34
A20: Ninja PO#2600651819 | B20: 46235 | C20: 1215.17 | D20: =$B$2 -> 0.04 | E20: =ROUND(C20*$B$2,2) -> 48.61
A21: Invoice total | C21: =SUM(C19:C20) -> 3223.77 | E21: =SUM(E19:E20) -> 128.95
