Workbook

Sheet High & Urgent Leads
A1: # | B1: Lead / Brand | C1: Status | D1: Priority | E1: Assignee(s) | F1: Lead Source | G1: Contact Person | H1: Phone | I1: City | J1: Store URL | K1: Started Date | L1: Closing Date | M1: Due Date | N1: Created | O1: Last Updated | P1: Last Update (note) | Q1: ClickUp Link | R1: Task ID
A2: 1 | B2: Abdul Latif Jameel Electronics | C2: opportunity | D2: urgent | E2: mohamed eladawy | F2: mohamed eladawy | J2: https://alje.com/ | N2: 46273.489 | O2: 46273.514 | Q2: https://app.clickup.com/t/86eyv1h0g | R2: 86eyv1h0g
A3: 2 | B3: Al-Ahli Club Company | C3: opportunity | D3: urgent | E3: mohamed eladawy | F3: mohamed eladawy | N3: 46272.722 | O3: 46272.723 | Q3: https://app.clickup.com/t/86eyuxng0 | R3: 86eyuxng0
A4: 3 | B4: al-asasyah | C4: opportunity | D4: urgent | E4: mohamed eladawy | F4: mohamed eladawy | J4: https://al-asasyah.com/new/ | N4: 46272.704 | O4: 46272.706 | Q4: https://app.clickup.com/t/86eyuxhjq | R4: 86eyuxhjq
A5: 4 | B5: aromatic للعطور | C5: opportunity | D5: urgent | E5: mohamed eladawy | F5: mohamed eladawy | M5: 46267.167 | N5: 46148.562 | O5: 46267.556 | Q5: https://app.clickup.com/t/86exgvxwr | R5: 86exgvxwr
A6: 5 | B6: Berain Water | C6: opportunity | D6: urgent | E6: mohamed eladawy | F6: mohamed eladawy | J6: https://berain.com.sa/ | N6: 46272.714 | O6: 46272.716 | Q6: https://app.clickup.com/t/86eyuxmck | R6: 86eyuxmck
A7: 6 | B7: Beyyak | C7: opportunity | D7: urgent | E7: Ibrahim Alothman, Tarik Alotay, mohamed eladawy | F7: mohamed eladawy | H7: 966562916940 | I7: Riyadh | J7: https://mahally.com/en/stores/2144568613/ | M7: 46296.167 | N7: 46076.484 | O7: 46271.799 | Q7: https://app.clickup.com/t/86ewpmcdh | R7: 86ewpmcdh
A8: 7 | B8: Black Stamp Roastery | C8: opportunity | D8: urgent | E8: mohamed eladawy | F8: mohamed eladawy | N8: 46155.557 | O8: 46243.701 | Q8: https://app.clickup.com/t/86exker91 | R8: 86exker91
A9: 8 | B9: Blends | C9: opportunity | D9: urgent | E9: mohamed eladawy | F9: mohamed eladawy | N9: 46159.757 | O9: 46261.64 | Q9: https://app.clickup.com/t/86exmrv1x | R9: 86exmrv1x
A10: 9 | B10: Brio | C10: opportunity | D10: urgent | E10: mohamed eladawy | F10: mohamed eladawy | N10: 46155.685 | O10: 46243.701 | Q10: https://app.clickup.com/t/86exkgpcv | R10: 86exkgpcv
A11: 10 | B11: Casio | C11: opportunity | D11: urgent | E11: mohamed eladawy | F11: mohamed eladawy | J11: https://shop.abbar-sa.com/ | N11: 46253.702 | O11: 46259.774 | Q11: https://app.clickup.com/t/86eyp7bc7 | R11: 86eyp7bc7
A12: 11 | B12: coffeesouq | C12: opportunity | D12: urgent | E12: mohamed eladawy | F12: mohamed eladawy | H12: 966540659336 | I12: Al Khobar | J12: https://mahally.com/en/stores/1658035366/ | N12: 46125.647 | O12: 46271.8 | Q12: https://app.clickup.com/t/86ex84c2v | R12: 86ex84c2v
A13: 12 | B13: draljamal | C13: opportunity | D13: urgent | E13: mohamed eladawy | F13: mohamed eladawy | H13: 966591416922 | I13: Riyadh | J13: https://mahally.com/en/stores/1017839016/ | M13: 46270.167 | N13: 46140.626 | O13: 46271.8 | Q13: https://app.clickup.com/t/86exdrtkf | R13: 86exdrtkf
A14: 13 | B14: electroon | C14: opportunity | D14: urgent | E14: mohamed eladawy | F14: mohamed eladawy | N14: 46078.545 | O14: 46254.652 | Q14: https://app.clickup.com/t/86ewqn8tq | R14: 86ewqn8tq
A15: 14 | B15: Freesiashop | C15: opportunity | D15: urgent | E15: mohamed eladawy | F15: mohamed eladawy | N15: 46166.764 | O15: 46259.709 | Q15: https://app.clickup.com/t/86exqc0uw | R15: 86exqc0uw
A16: 15 | B16: grocerjy | C16: opportunity | D16: urgent | E16: mohamed eladawy | F16: mohamed eladawy | J16: https://grocerjy.com/ | N16: 46098.549 | O16: 46260.501 | Q16: https://app.clickup.com/t/86ewyxjrq | R16: 86ewyxjrq
A17: 16 | B17: House - إن هاوس | C17: opportunity | D17: urgent | E17: mohamed eladawy | F17: mohamed eladawy | J17: https://inhouse.sa/ar/ | N17: 46272.71 | O17: 46272.711 | Q17: https://app.clickup.com/t/86eyuxkft | R17: 86eyuxkft
A18: 17 | B18: hugezone | C18: opportunity | D18: urgent | E18: mohamed eladawy | F18: mohamed eladawy | H18: 966501449806 | I18: Riyadh | J18: https://mahally.com/en/stores/1564904143/ | M18: 46295.167 | N18: 46098.635 | O18: 46271.8 | Q18: https://app.clickup.com/t/86ewyytvq | R18: 86ewyytvq
A19: 18 | B19: Lines | C19: opportunity | D19: urgent | E19: mohamed eladawy | F19: mohamed eladawy | H19: 966599308716 | I19: Almajaridah | J19: https://mahally.com/en/stores/675718663/ | N19: 46166.763 | O19: 46271.8 | Q19: https://app.clickup.com/t/86exqc0r7 | R19: 86exqc0r7
A20: 19 | B20: modernsupply | C20: opportunity | D20: urgent | E20: mohamed eladawy | F20: mohamed eladawy | N20: 46085.642 | O20: 46260.454 | Q20: https://app.clickup.com/t/86ewu7hjc | R20: 86ewu7hjc
A21: 20 | B21: nmastores | C21: opportunity | D21: urgent | E21: mohamed eladawy | F21: mohamed eladawy | N21: 46093.649 | O21: 46260.456 | Q21: https://app.clickup.com/t/86ewx8qvn | R21: 86ewx8qvn
A22: 21 | B22: Nova Water | C22: opportunity | D22: urgent | E22: mohamed eladawy | F22: mohamed eladawy | J22: https://novawater.com/ | N22: 46272.711 | O22: 46272.714 | Q22: https://app.clickup.com/t/86eyuxkwa | R22: 86eyuxkwa
A23: 22 | B23: option-b | C23: opportunity | D23: urgent | E23: mohamed eladawy | F23: mohamed eladawy | H23: 966543665012 | I23: Riyadh | J23: https://mahally.com/en/stores/779771963/ | N23: 46097.628 | O23: 46271.8 | Q23: https://app.clickup.com/t/86ewyhebj | R23: 86ewyhebj
A24: 23 | B24: rafahiacoffee | C24: opportunity | D24: urgent | E24: mohamed eladawy | F24: mohamed eladawy | N24: 46098.646 | O24: 46238.544 | Q24: https://app.clickup.com/t/86ewyywvc | R24: 86ewyywvc
A25: 24 | B25: Savola Group | C25: opportunity | D25: urgent | E25: mohamed eladawy | F25: mohamed eladawy | N25: 46272.725 | O25: 46272.727 | Q25: https://app.clickup.com/t/86eyuxp0v | R25: 86eyuxp0v
A26: 25 | B26: Shelf | C26: opportunity | D26: urgent | E26: mohamed eladawy | F26: mohamed eladawy | H26: 966560083734 | I26: Al Ahsa | J26: https://mahally.com/en/stores/1991402881/ | N26: 46159.656 | O26: 46271.8 | Q26: https://app.clickup.com/t/86exmqunx | R26: 86exmqunx
A27: 26 | B27: sleepbox | C27: opportunity | D27: urgent | E27: mohamed eladawy | F27: mohamed eladawy | M27: 46269.167 | N27: 46097.634 | O27: 46260.654 | Q27: https://app.clickup.com/t/86ewyhgn0 | R27: 86ewyhgn0
A28: 27 | B28: Swis sstar | C28: opportunity | D28: urgent | E28: mohamed eladawy | F28: mohamed eladawy | H28: 966501117930 | I28: Khamis Mushait | J28: https://mahally.com/en/stores/1680923228/ | N28: 46159.689 | O28: 46271.8 | Q28: https://app.clickup.com/t/86exmr2vb | R28: 86exmr2vb
A29: 28 | B29: wixtore | C29: opportunity | D29: urgent | E29: mohamed eladawy | F29: mohamed eladawy | N29: 46127.652 | O29: 46238.631 | Q29: https://app.clickup.com/t/86ex8z087 | R29: 86ex8z087
A30: 29 | B30: ابراق | C30: opportunity | D30: urgent | E30: mohamed eladawy | F30: mohamed eladawy | M30: 46292.167 | N30: 46068.656 | O30: 46272.577 | Q30: https://app.clickup.com/t/86ewm55vt | R30: 86ewm55vt
A31: 30 | B31: العراب | C31: opportunity | D31: urgent | E31: mohamed eladawy | F31: mohamed eladawy | H31: 920000152 | I31: Buraydah | J31: https://mahally.com/en/stores/862218137/ | N31: 46162.614 | O31: 46271.8 | Q31: https://app.clickup.com/t/86exnz8rk | R31: 86exnz8rk
A32: 31 | B32: باتونيا | C32: opportunity | D32: urgent | E32: Ibrahim Alothman, mohamed eladawy | F32: Tarik Alotay | H32: 966553533997 | I32: Riyadh | J32: https://batonia.com/ | N32: 45879.771 | O32: 46271.8 | Q32: https://app.clickup.com/t/86euermyn | R32: 86euermyn
A33: 32 | B33: جوادير | C33: opportunity | D33: urgent | E33: mohamed eladawy | F33: mohamed eladawy | N33: 46155.709 | O33: 46251.709 | Q33: https://app.clickup.com/t/86exkh1y9 | R33: 86exkh1y9
A34: 33 | B34: خطوه جمل | C34: opportunity | D34: urgent | E34: mohamed eladawy | F34: mohamed eladawy | N34: 46152.645 | O34: 46243.702 | Q34: https://app.clickup.com/t/86exj2hky | R34: 86exj2hky
A35: 34 | B35: ركن السرير | C35: opportunity | D35: urgent | E35: mohamed eladawy | F35: mohamed eladawy | N35: 46155.58 | O35: 46261.696 | Q35: https://app.clickup.com/t/86exkf99d | R35: 86exkf99d
A36: 35 | B36: زد كب | C36: opportunity | D36: urgent | E36: mohamed eladawy | F36: mohamed eladawy | H36: 966508591561 | I36: Addayer | J36: https://mahally.com/en/stores/182989462/ | N36: 46158.616 | O36: 46271.8 | Q36: https://app.clickup.com/t/86exmje5m | R36: 86exmje5m
A37: 36 | B37: زرافة | C37: opportunity | D37: urgent | E37: mohamed eladawy | F37: mohamed eladawy | H37: 966534115111 | I37: Riyadh | J37: https://mahally.com/en/stores/1461081935/ | N37: 46151.56 | O37: 46271.8 | Q37: https://app.clickup.com/t/86exhx2fp | R37: 86exhx2fp
A38: 37 | B38: شركة بنتي للصناعة | C38: opportunity | D38: urgent | E38: mohamed eladawy | F38: mohamed eladawy | N38: 46173.752 | O38: 46243.694 | Q38: https://app.clickup.com/t/86extcnzm | R38: 86extcnzm
A39: 38 | B39: شركة رياحين | C39: opportunity | D39: urgent | E39: mohamed eladawy | F39: mohamed eladawy | N39: 46173.748 | O39: 46243.694 | Q39: https://app.clickup.com/t/86extcj9k | R39: 86extcj9k
A40: 39 | B40: عالم الصفوه | C40: opportunity | D40: urgent | E40: mohamed eladawy | F40: mohamed eladawy | N40: 46159.638 | O40: 46243.699 | Q40: https://app.clickup.com/t/86exmqnjt | R40: 86exmqnjt
...

Sheet Summary
A1: Nasam — Brands Leads export
A3: Source | B3: ClickUp › Nasam Growth › Brands Leads (list 901809161015)
A4: Filter | B4: Status is NOT "lead" AND Priority is High or Urgent
A5: Leads in list | B5: 6067
A6: Leads exported | B6: ='High & Urgent Leads'!A285 -> 284
A7: Pulled | B7: 2026-09-09 16:25 (Riyadh)
A9: Breakdown — status × priority
A10: Status | B10: Urgent | C10: High | D10: Total
A11: opportunity | B11: =COUNTIFS('High & Urgent Leads'!$C$2:$C$285,$A11,'High & Urgent Leads'!$D$2:$D$285,B$10) -> 50 | C11: =COUNTIFS('High & Urgent Leads'!$C$2:$C$285,$A11,'High & Urgent Leads'!$D$2:$D$285,C$10) -> 60 | D11: =SUM(B11:C11) -> 110
A12: propose | B12: =COUNTIFS('High & Urgent Leads'!$C$2:$C$285,$A12,'High & Urgent Leads'!$D$2:$D$285,B$10) -> 6 | C12: =COUNTIFS('High & Urgent Leads'!$C$2:$C$285,$A12,'High & Urgent Leads'!$D$2:$D$285,C$10) -> 2 | D12: =SUM(B12:C12) -> 8
A13: meeting | B13: =COUNTIFS('High & Urgent Leads'!$C$2:$C$285,$A13,'High & Urgent Leads'!$D$2:$D$285,B$10) -> 11 | C13: =COUNTIFS('High & Urgent Leads'!$C$2:$C$285,$A13,'High & Urgent Leads'!$D$2:$D$285,C$10) -> 2 | D13: =SUM(B13:C13) -> 13
A14: approved | B14: =COUNTIFS('High & Urgent Leads'!$C$2:$C$285,$A14,'High & Urgent Leads'!$D$2:$D$285,B$10) -> 2 | C14: =COUNTIFS('High & Urgent Leads'!$C$2:$C$285,$A14,'High & Urgent Leads'!$D$2:$D$285,C$10) -> 2 | D14: =SUM(B14:C14) -> 4
A15: postpone | B15: =COUNTIFS('High & Urgent Leads'!$C$2:$C$285,$A15,'High & Urgent Leads'!$D$2:$D$285,B$10) -> 39 | C15: =COUNTIFS('High & Urgent Leads'!$C$2:$C$285,$A15,'High & Urgent Leads'!$D$2:$D$285,C$10) -> 57 | D15: =SUM(B15:C15) -> 96
A16: rejected | B16: =COUNTIFS('High & Urgent Leads'!$C$2:$C$285,$A16,'High & Urgent Leads'!$D$2:$D$285,B$10) -> 24 | C16: =COUNTIFS('High & Urgent Leads'!$C$2:$C$285,$A16,'High & Urgent Leads'!$D$2:$D$285,C$10) -> 20 | D16: =SUM(B16:C16) -> 44
A17: churned | B17: =COUNTIFS('High & Urgent Leads'!$C$2:$C$285,$A17,'High & Urgent Leads'!$D$2:$D$285,B$10) -> 6 | C17: =COUNTIFS('High & Urgent Leads'!$C$2:$C$285,$A17,'High & Urgent Leads'!$D$2:$D$285,C$10) -> 3 | D17: =SUM(B17:C17) -> 9
A18: Total | B18: =SUM(B11:B17) -> 138 | C18: =SUM(C11:C17) -> 146 | D18: =SUM(D11:D17) -> 284
A20: Notes: counts are COUNTIFS formulas over the "High & Urgent Leads" sheet, so they follow any row you delete or re-filter.
A21: Phone and City are parsed from the ClickUp task description and are blank where the task carries no description.
A22: Dates are shown in Riyadh time (UTC+3). Blank means the field is empty in ClickUp.
